1:
import pymysql as pm
try:
    con = pm.connect(host='localhost', database='acadviewdb', user='root', password='ritu123')
    cursor = con.cursor()
    query6 = 'Create table Authors(AuthorID int primary key,FirstName varchar(15),MiddleName varchar(15),LastName varchar(15))'
    cursor.execute(query6)
    query4 = 'Create table Zip_Codes(Zip_Code_ID int primary key,City varchar(15),State varchar(20),Zip_Code int)'
    cursor.execute(query4)
    query3 = 'Create table Publishers(Publisher_ID int primary key,Name varchar(15),Street_Address varchar(50),\
    Suite_Number int,Zip_Code_ID int,foreign key(Zip_Code_ID) references Zip_Codes(Zip_Code_ID))'
    cursor.execute(query3)
    query2 = 'Create table Titles(TitleId int primary key,Title varchar(35),ISBN int,Publisher_ID int,Publication_Year int,\
    foreign key(Publisher_ID) references Publishers(Publisher_ID))'
    cursor.execute(query2)
    query1 = 'Create table Books(BookId int primary key,TitleId int,Location varchar(15),Genre varchar(10),\
    foreign key(TitleId) references Titles(TitleId))'
    cursor.execute(query1)
    query5 = 'Create table Authors_Titles(Author_Title_ID int primary key,AuthorID int ,TitleId int,\
    foreign key(AuthorID) references Authors(AuthorID),foreign key(TitleId) references Titles(TitleId))'
    cursor.execute(query5)
    print('Table Created')

except pm.DatabaseError as e:
    if con:
        con.rollback()
        print('Problem occured: ', e)

finally:
    if cursor:
        cursor.close()
    if con:
        con.close()
    print('DONE!!')
output:
Table Created
DONE!!

2:
import pymysql as pm
try:
    con = pm.connect(host='localhost', database='acadviewdb', user='root', password='ritu123')
    cursor = con.cursor()
    query1 = "insert into authors values (206,'A','D','Roy'),(207,'R','K','Narayan'),\
    (208,'S','L','Rushday'),(209,'R','K','Bond'),(210,'J','W','Nehru')"
    cursor.execute(query1)

    query2 = "insert into zip_codes values (2,'UttarPradesh','Lucknow',249014),(4,'Dehradun','Uttarakhand',248001),\
    (3,'Maharashtra','Mumbai',34987),(1,'UttarPradesh','Lucknow',249014),(5,'Rajasthan','Jaipur',123456)"
    cursor.execute(query2)

    query3 = "insert into publishers values(12,'VK Garg','Old Warriors Colony',51,2),(11,'Praful Kumar','Prasang Vihar',53,4),\
    (10,'AK Gupta','Vijender Nagar',55,3),(13,'Rahul Gupta','Ramvilas Vihar',54,1),(14,'Riya Sen','Sharol Bagh',57,5)"
    cursor.execute(query3)

    query4 = "insert into titles values (22,'ASongOfIce',1001,12,2005),(21,'GobletOfFire',1002,11,2003),\
    (23,'TheLoadRunner',1003,10,2014),(24,'FivePointThreeTw',1004,14,2012),(25,'NeedNoReasons',1005,13,2015)"
    cursor.execute(query4)

    query5 = "insert into books values (20,21,'Hyderabad','Thriller'),(21,23,'Bangalore','Classic'),\
    (22,22,'NewDelhi','Romantic'),(23,25,'Kolkata','HateStory'),(24,24,'Chandigarh','Comedy')"
    cursor.execute(query5)

    query6 = "insert into authors_titles values (556,206,21),(557,207,22),(558,208,24),(559,209,23),(560,210,25)"
    cursor.execute(query6)

    con.commit()
except pm.DatabaseError as e:
    if con:
        con.rollback()
        print('Problem occured: ', e)
finally:
    if cursor:
        cursor.close()
    if con:
        con.close()
    print('DONE!!')
output:

DONE!!

3:
import pymysql as pm
try:
    con = pm.connect(host='localhost', database='acadviewdb', user='root', password='ritu123')
    cursor = con.cursor()
    query1 = "Select * from Publishers where Publisher_ID=14"
    cursor.execute(query1)
    data = cursor.fetchall()
    for row in data:
        print('Publisher_ID: {}, Name: {}, Street_Adress: {}, Suite_Number: {}, Zip_Code_ID: {}' \
              .format(row[0], row[1], row[2], row[3], row[4]))
    query2 = "Update Publishers set Street_Address='Canal Road' where Publisher_ID=14"
    cursor.execute(query2)
    con.commit()

    print("\nUpdated Table:")
    query3 = "Select * from Publishers"
    cursor.execute(query3)
    d = cursor.fetchall()
    for row in d:
        print('Publisher_ID: {}, Name: {}, Street_Adress: {}, Suite_Number: {}, Zip_Code_ID: {}' \
              .format(row[0], row[1], row[2], row[3], row[4]))

except pm.DatabaseError as e:
    if con:
        con.rollback()
        print('Problem occured: ', e)

finally:
    if cursor:
        cursor.close()
    if con:
        con.close()
    print('\nDONE!!')

output:
C:\Users\win10\PycharmProjects\python\venv\Scripts\python.exe C:/Users/win10/PycharmProjects/python/venv/database3.py
Publisher_ID: 14, Name: Riya Sen, Street_Adress: Canal Road, Suite_Number: 57, Zip_Code_ID: 5

Updated Table:
Publisher_ID: 10, Name: AK Gupta, Street_Adress: Vijender Nagar, Suite_Number: 55, Zip_Code_ID: 3
Publisher_ID: 11, Name: Praful Kumar, Street_Adress: Prasang Vihar, Suite_Number: 53, Zip_Code_ID: 4
Publisher_ID: 12, Name: VK Garg, Street_Adress: Old Warriors Colony, Suite_Number: 51, Zip_Code_ID: 2
Publisher_ID: 13, Name: Rahul Gupta, Street_Adress: Ramvilas Vihar, Suite_Number: 54, Zip_Code_ID: 1
Publisher_ID: 14, Name: Riya Sen, Street_Adress: Canal Road, Suite_Number: 57, Zip_Code_ID: 5

DONE!!

Process finished with exit code 0

